Random testing using config=Config(swarmSwitch=None, maxMustHitBranch=None, verbose=False, reducePool=False, failedLogging=None, exploitBestHint=1, greedyStutter=False, internal=False, exploit=None, seed=None, generalize=False, fastQuickAnalysis=False, stopWhenNoCoverage=None, useHints=False, localize=False, total=False, speed='FAST', probs=None, normalize=False, verboseExploit=False, highLowSwarm=None, replayable=False, essentials=False, maxMustHitStatement=None, noCoverageExploit=False, quickTests=False, relax=False, startExploitStall=0, enumerateEnabled=False, uniqueValuesAnalysis=False, swarm=False, noReassign=False, html=None, stopWhenHitStatement=None, biasLOC=None, progress=False, postCover=False, swarmLength=None, generateLOC=None, noSwarmDependencies=False, profile=False, LOCBaseline=0.2, noEnumerateEnabled=False, full=True, multiple=False, timedProgress=30, silentFail=False, ddmin=False, swarmP=0.5, stopWhenBranches=None, noAlphaConvert=False, coverFile='coverage.out', readQuick=False, verboseActions=False, running=False, computeFeatureStats=False, compareFails=False, swarmProbs=None, output='failure.61024.test', genDepth=None, Pcrossover=0.2, quickAnalysis=False, keepLast=False, exploitCeiling=0.1, markovP=1.0, logging=None, stopWhenHitBranch=None, LOCProbs=False, stopWhenStatements=None, noCheck=False, maxTests=-1, noExceptionMatch=False, Pmutate=0.0, depth=200, trackMaxCoverage=None, throughput=False, noCover=True, timeout=60, stutter=None, uncaught=False, markov=None, showActions=False, startExploit=0.0)
UNCAUGHT EXCEPTION
ERROR: (<type 'exceptions.OSError'>, OSError(17, 'Object already exists in fake filesystem'), <traceback object at 0x104b1f710>)
TRACEBACK:
  File "/Users/alex/tstl/examples/mutateProbe/pyfakefs/sut.py", line 48329, in safely
    act[2]()
  File "/Users/alex/tstl/examples/mutateProbe/pyfakefs/sut.py", line 66, in act0
    self.p_os[0] = newFakeOS()
  File "/Users/alex/tstl/examples/mutateProbe/pyfakefs/sut.py", line 22, in newFakeOS
    fs.CreateDirectory('/Volumes/ramdisk')
  File "/Users/alex/tstl/examples/mutateProbe/pyfakefs/pyfakefs/fake_filesystem.py", line 2075, in CreateDirectory
    current_dir.AddEntry(new_dir)
  File "/Users/alex/tstl/examples/mutateProbe/pyfakefs/pyfakefs/fake_filesystem.py", line 689, in AddEntry
    raise OSError(errno.EEXIST, 'Object already exists in fake filesystem', self.GetPath())
Original test has 8 steps

SAVING TEST AS failure.61024.test
FINAL VERSION OF TEST, WITH LOGGED REPLAY:
component3 = "e"                                                         # STEP 0
ACTION: component3 = "e" 
component3 = None : <type 'NoneType'>
=> component3 = 'e' : <type 'str'>
==================================================
component2 = "phi"                                                       # STEP 1
ACTION: component2 = "phi" 
component2 = None : <type 'NoneType'>
=> component2 = 'phi' : <type 'str'>
==================================================
component4 = "phi"                                                       # STEP 2
ACTION: component4 = "phi" 
component4 = None : <type 'NoneType'>
=> component4 = 'phi' : <type 'str'>
==================================================
bytes1 = 0                                                               # STEP 3
ACTION: bytes1 = 0 
bytes1 = None : <type 'NoneType'>
=> bytes1 = 0 : <type 'int'>
==================================================
component0 = "alpha"                                                     # STEP 4
ACTION: component0 = "alpha" 
component0 = None : <type 'NoneType'>
=> component0 = 'alpha' : <type 'str'>
==================================================
component1 = "f"                                                         # STEP 5
ACTION: component1 = "f" 
component1 = None : <type 'NoneType'>
=> component1 = 'f' : <type 'str'>
==================================================
bytes4 = 0                                                               # STEP 6
ACTION: bytes4 = 0 
bytes4 = None : <type 'NoneType'>
=> bytes4 = 0 : <type 'int'>
==================================================
os0 = newFakeOS()                                                        # STEP 7
ACTION: os0 = newFakeOS() 
os0 = None : <type 'NoneType'>
os_REF0 = None : <type 'NoneType'>
RAISED EXCEPTION: <type 'exceptions.OSError'> [Errno 17] Object already exists in fake filesystem: '/'
ERROR: (<type 'exceptions.OSError'>, OSError(17, 'Object already exists in fake filesystem'), <traceback object at 0x104f4cef0>)
TRACEBACK:
  File "/Users/alex/tstl/examples/mutateProbe/pyfakefs/sut.py", line 48329, in safely
    act[2]()
  File "/Users/alex/tstl/examples/mutateProbe/pyfakefs/sut.py", line 66, in act0
    self.p_os[0] = newFakeOS()
  File "/Users/alex/tstl/examples/mutateProbe/pyfakefs/sut.py", line 22, in newFakeOS
    fs.CreateDirectory('/Volumes/ramdisk')
  File "/Users/alex/tstl/examples/mutateProbe/pyfakefs/pyfakefs/fake_filesystem.py", line 2075, in CreateDirectory
    current_dir.AddEntry(new_dir)
  File "/Users/alex/tstl/examples/mutateProbe/pyfakefs/pyfakefs/fake_filesystem.py", line 689, in AddEntry
    raise OSError(errno.EEXIST, 'Object already exists in fake filesystem', self.GetPath())
STOPPING TESTING DUE TO FAILED TEST
0.0456969738007 TOTAL RUNTIME
2 EXECUTED
208 TOTAL TEST OPERATIONS
0.00472664833069 TIME SPENT EXECUTING TEST OPERATIONS
0.0131874084473 TIME SPENT EVALUATING GUARDS AND CHOOSING ACTIONS
0.000105381011963 TIME SPENT CHECKING PROPERTIES
0.00483202934265 TOTAL TIME SPENT RUNNING SUT
0.00773406028748 TIME SPENT RESTARTING
0.0 TIME SPENT REDUCING TEST CASES
