Random testing using config=Config(swarmSwitch=None, maxMustHitBranch=None, verbose=False, reducePool=False, failedLogging=None, exploitBestHint=1, greedyStutter=False, internal=False, exploit=None, seed=None, generalize=False, fastQuickAnalysis=False, stopWhenNoCoverage=None, useHints=False, localize=False, total=False, speed='FAST', probs=None, normalize=False, verboseExploit=False, highLowSwarm=None, replayable=False, essentials=False, maxMustHitStatement=None, noCoverageExploit=False, quickTests=False, relax=False, startExploitStall=0, enumerateEnabled=False, uniqueValuesAnalysis=False, swarm=False, noReassign=False, html=None, stopWhenHitStatement=None, biasLOC=None, progress=False, postCover=False, swarmLength=None, generateLOC=None, noSwarmDependencies=False, profile=False, LOCBaseline=0.2, noEnumerateEnabled=False, full=True, multiple=False, timedProgress=30, silentFail=False, ddmin=False, swarmP=0.5, stopWhenBranches=None, noAlphaConvert=False, coverFile='coverage.out', readQuick=False, verboseActions=False, running=False, computeFeatureStats=False, compareFails=False, swarmProbs=None, output='failure.50090.test', genDepth=None, Pcrossover=0.2, quickAnalysis=False, keepLast=False, exploitCeiling=0.1, markovP=1.0, logging=None, stopWhenHitBranch=None, LOCProbs=False, stopWhenStatements=None, noCheck=False, maxTests=-1, noExceptionMatch=False, Pmutate=0.0, depth=200, trackMaxCoverage=None, throughput=False, noCover=True, timeout=60, stutter=None, uncaught=False, markov=None, showActions=False, startExploit=0.0)
UNCAUGHT EXCEPTION
ERROR: (<type 'exceptions.OSError'>, OSError(17, 'Directory exists in fake filesystem'), <traceback object at 0x1033fb950>)
TRACEBACK:
  File "/Users/alex/tstl/examples/mutateProbe/pyfakefs/sut.py", line 48329, in safely
    act[2]()
  File "/Users/alex/tstl/examples/mutateProbe/pyfakefs/sut.py", line 66, in act0
    self.p_os[0] = newFakeOS()
  File "/Users/alex/tstl/examples/mutateProbe/pyfakefs/sut.py", line 21, in newFakeOS
    fs.CreateDirectory('/Volumes')
  File "/Users/alex/tstl/examples/mutateProbe/pyfakefs/pyfakefs/fake_filesystem.py", line 2057, in CreateDirectory
    raise OSError(errno.EEXIST, 'Directory exists in fake filesystem', directory_path)
Original test has 8 steps

SAVING TEST AS failure.50090.test
FINAL VERSION OF TEST, WITH LOGGED REPLAY:
component2 = "b"                                                         # STEP 0
ACTION: component2 = "b" 
component2 = None : <type 'NoneType'>
=> component2 = 'b' : <type 'str'>
==================================================
component4 = "phi"                                                       # STEP 1
ACTION: component4 = "phi" 
component4 = None : <type 'NoneType'>
=> component4 = 'phi' : <type 'str'>
==================================================
component3 = "alpha"                                                     # STEP 2
ACTION: component3 = "alpha" 
component3 = None : <type 'NoneType'>
=> component3 = 'alpha' : <type 'str'>
==================================================
bytes0 = 0                                                               # STEP 3
ACTION: bytes0 = 0 
bytes0 = None : <type 'NoneType'>
=> bytes0 = 0 : <type 'int'>
==================================================
component0 = "omega"                                                     # STEP 4
ACTION: component0 = "omega" 
component0 = None : <type 'NoneType'>
=> component0 = 'omega' : <type 'str'>
==================================================
component1 = "lambda"                                                    # STEP 5
ACTION: component1 = "lambda" 
component1 = None : <type 'NoneType'>
=> component1 = 'lambda' : <type 'str'>
==================================================
path3 = "/Volumes/ramdisk/test"                                          # STEP 6
ACTION: path3 = "/Volumes/ramdisk/test" 
path3 = None : <type 'NoneType'>
=> path3 = '/Volumes/ramdisk/test' : <type 'str'>
==================================================
os0 = newFakeOS()                                                        # STEP 7
ACTION: os0 = newFakeOS() 
os0 = None : <type 'NoneType'>
os_REF0 = None : <type 'NoneType'>
RAISED EXCEPTION: <type 'exceptions.OSError'> [Errno 17] Directory exists in fake filesystem: '/Volumes'
ERROR: (<type 'exceptions.OSError'>, OSError(17, 'Directory exists in fake filesystem'), <traceback object at 0x103427b48>)
TRACEBACK:
  File "/Users/alex/tstl/examples/mutateProbe/pyfakefs/sut.py", line 48329, in safely
    act[2]()
  File "/Users/alex/tstl/examples/mutateProbe/pyfakefs/sut.py", line 66, in act0
    self.p_os[0] = newFakeOS()
  File "/Users/alex/tstl/examples/mutateProbe/pyfakefs/sut.py", line 21, in newFakeOS
    fs.CreateDirectory('/Volumes')
  File "/Users/alex/tstl/examples/mutateProbe/pyfakefs/pyfakefs/fake_filesystem.py", line 2057, in CreateDirectory
    raise OSError(errno.EEXIST, 'Directory exists in fake filesystem', directory_path)
STOPPING TESTING DUE TO FAILED TEST
0.021087884903 TOTAL RUNTIME
1 EXECUTED
8 TOTAL TEST OPERATIONS
0.000341892242432 TIME SPENT EXECUTING TEST OPERATIONS
0.000817775726318 TIME SPENT EVALUATING GUARDS AND CHOOSING ACTIONS
3.33786010742e-06 TIME SPENT CHECKING PROPERTIES
0.000345230102539 TOTAL TIME SPENT RUNNING SUT
0.00322103500366 TIME SPENT RESTARTING
0.0 TIME SPENT REDUCING TEST CASES
