Random testing using config=Config(swarmSwitch=None, maxMustHitBranch=None, verbose=False, reducePool=False, failedLogging=None, exploitBestHint=1, greedyStutter=False, internal=False, exploit=None, seed=None, generalize=False, fastQuickAnalysis=False, stopWhenNoCoverage=None, useHints=False, localize=False, total=False, speed='FAST', probs=None, normalize=False, verboseExploit=False, highLowSwarm=None, replayable=False, essentials=False, maxMustHitStatement=None, noCoverageExploit=False, quickTests=False, relax=False, startExploitStall=0, enumerateEnabled=False, uniqueValuesAnalysis=False, swarm=False, noReassign=False, html=None, stopWhenHitStatement=None, biasLOC=None, progress=False, postCover=False, swarmLength=None, generateLOC=None, noSwarmDependencies=False, profile=False, LOCBaseline=0.2, noEnumerateEnabled=False, full=True, multiple=False, timedProgress=30, silentFail=False, ddmin=False, swarmP=0.5, stopWhenBranches=None, noAlphaConvert=False, coverFile='coverage.out', readQuick=False, verboseActions=False, running=False, computeFeatureStats=False, compareFails=False, swarmProbs=None, output='failure.62038.test', genDepth=None, Pcrossover=0.2, quickAnalysis=False, keepLast=False, exploitCeiling=0.1, markovP=1.0, logging=None, stopWhenHitBranch=None, LOCProbs=False, stopWhenStatements=None, noCheck=False, maxTests=-1, noExceptionMatch=False, Pmutate=0.0, depth=200, trackMaxCoverage=None, throughput=False, noCover=True, timeout=60, stutter=None, uncaught=False, markov=None, showActions=False, startExploit=0.0)
UNCAUGHT EXCEPTION
ERROR: (<type 'exceptions.OSError'>, OSError(17, 'Directory exists in fake filesystem'), <traceback object at 0x1007c32d8>)
TRACEBACK:
  File "/Users/alex/tstl/examples/mutateProbe/pyfakefs/sut.py", line 48329, in safely
    act[2]()
  File "/Users/alex/tstl/examples/mutateProbe/pyfakefs/sut.py", line 66, in act0
    self.p_os[0] = newFakeOS()
  File "/Users/alex/tstl/examples/mutateProbe/pyfakefs/sut.py", line 21, in newFakeOS
    fs.CreateDirectory('/Volumes')
  File "/Users/alex/tstl/examples/mutateProbe/pyfakefs/pyfakefs/fake_filesystem.py", line 2057, in CreateDirectory
    raise OSError(errno.EEXIST, 'Directory exists in fake filesystem', directory_path)
Original test has 7 steps

SAVING TEST AS failure.62038.test
FINAL VERSION OF TEST, WITH LOGGED REPLAY:
bytes3 = 0                                                               # STEP 0
ACTION: bytes3 = 0 
bytes3 = None : <type 'NoneType'>
=> bytes3 = 0 : <type 'int'>
==================================================
component2 = "e"                                                         # STEP 1
ACTION: component2 = "e" 
component2 = None : <type 'NoneType'>
=> component2 = 'e' : <type 'str'>
==================================================
path1 = "/Volumes/ramdisk/test"                                          # STEP 2
ACTION: path1 = "/Volumes/ramdisk/test" 
path1 = None : <type 'NoneType'>
=> path1 = '/Volumes/ramdisk/test' : <type 'str'>
==================================================
path2 = "/Volumes/ramdisk/test"                                          # STEP 3
ACTION: path2 = "/Volumes/ramdisk/test" 
path2 = None : <type 'NoneType'>
=> path2 = '/Volumes/ramdisk/test' : <type 'str'>
==================================================
component0 = "g"                                                         # STEP 4
ACTION: component0 = "g" 
component0 = None : <type 'NoneType'>
=> component0 = 'g' : <type 'str'>
==================================================
component4 = "c"                                                         # STEP 5
ACTION: component4 = "c" 
component4 = None : <type 'NoneType'>
=> component4 = 'c' : <type 'str'>
==================================================
os0 = newFakeOS()                                                        # STEP 6
ACTION: os0 = newFakeOS() 
os0 = None : <type 'NoneType'>
os_REF0 = None : <type 'NoneType'>
RAISED EXCEPTION: <type 'exceptions.OSError'> [Errno 17] Directory exists in fake filesystem: '/Volumes'
ERROR: (<type 'exceptions.OSError'>, OSError(17, 'Directory exists in fake filesystem'), <traceback object at 0x1031b35a8>)
TRACEBACK:
  File "/Users/alex/tstl/examples/mutateProbe/pyfakefs/sut.py", line 48329, in safely
    act[2]()
  File "/Users/alex/tstl/examples/mutateProbe/pyfakefs/sut.py", line 66, in act0
    self.p_os[0] = newFakeOS()
  File "/Users/alex/tstl/examples/mutateProbe/pyfakefs/sut.py", line 21, in newFakeOS
    fs.CreateDirectory('/Volumes')
  File "/Users/alex/tstl/examples/mutateProbe/pyfakefs/pyfakefs/fake_filesystem.py", line 2057, in CreateDirectory
    raise OSError(errno.EEXIST, 'Directory exists in fake filesystem', directory_path)
STOPPING TESTING DUE TO FAILED TEST
0.033145904541 TOTAL RUNTIME
2 EXECUTED
207 TOTAL TEST OPERATIONS
0.00329351425171 TIME SPENT EXECUTING TEST OPERATIONS
0.00936841964722 TIME SPENT EVALUATING GUARDS AND CHOOSING ACTIONS
9.10758972168e-05 TIME SPENT CHECKING PROPERTIES
0.00338459014893 TOTAL TIME SPENT RUNNING SUT
0.00533413887024 TIME SPENT RESTARTING
0.0 TIME SPENT REDUCING TEST CASES
