Random testing using config=Config(swarmSwitch=None, maxMustHitBranch=None, verbose=False, reducePool=False, failedLogging=None, exploitBestHint=1, greedyStutter=False, internal=False, exploit=None, seed=None, generalize=False, fastQuickAnalysis=False, stopWhenNoCoverage=None, useHints=False, localize=False, total=False, speed='FAST', probs=None, normalize=False, verboseExploit=False, highLowSwarm=None, replayable=False, essentials=False, maxMustHitStatement=None, noCoverageExploit=False, quickTests=False, relax=False, startExploitStall=0, enumerateEnabled=False, uniqueValuesAnalysis=False, swarm=False, noReassign=False, html=None, stopWhenHitStatement=None, biasLOC=None, progress=False, postCover=False, swarmLength=None, generateLOC=None, noSwarmDependencies=False, profile=False, LOCBaseline=0.2, noEnumerateEnabled=False, full=True, multiple=False, timedProgress=30, silentFail=False, ddmin=False, swarmP=0.5, stopWhenBranches=None, noAlphaConvert=False, coverFile='coverage.out', readQuick=False, verboseActions=False, running=False, computeFeatureStats=False, compareFails=False, swarmProbs=None, output='failure.54028.test', genDepth=None, Pcrossover=0.2, quickAnalysis=False, keepLast=False, exploitCeiling=0.1, markovP=1.0, logging=None, stopWhenHitBranch=None, LOCProbs=False, stopWhenStatements=None, noCheck=False, maxTests=-1, noExceptionMatch=False, Pmutate=0.0, depth=200, trackMaxCoverage=None, throughput=False, noCover=True, timeout=60, stutter=None, uncaught=False, markov=None, showActions=False, startExploit=0.0)
UNCAUGHT EXCEPTION
ERROR: (<type 'exceptions.TypeError'>, TypeError('an integer is required',), <traceback object at 0x102779ea8>)
TRACEBACK:
  File "/Users/alex/tstl/examples/mutateProbe/pyfakefs/sut.py", line 48329, in safely
    act[2]()
  File "/Users/alex/tstl/examples/mutateProbe/pyfakefs/sut.py", line 66, in act0
    self.p_os[0] = newFakeOS()
  File "/Users/alex/tstl/examples/mutateProbe/pyfakefs/sut.py", line 21, in newFakeOS
    fs.CreateDirectory('/Volumes')
  File "/Users/alex/tstl/examples/mutateProbe/pyfakefs/pyfakefs/fake_filesystem.py", line 2055, in CreateDirectory
    if self.Exists(directory_path):
  File "/Users/alex/tstl/examples/mutateProbe/pyfakefs/pyfakefs/fake_filesystem.py", line 1624, in Exists
    file_path = self.ResolvePath(file_path)
  File "/Users/alex/tstl/examples/mutateProbe/pyfakefs/pyfakefs/fake_filesystem.py", line 1704, in ResolvePath
    return self.GetOpenFile(file_path).GetObject().GetPath()
  File "/Users/alex/tstl/examples/mutateProbe/pyfakefs/pyfakefs/fake_filesystem.py", line 1209, in GetOpenFile
    raise TypeError('an integer is required')
Original test has 5 steps

SAVING TEST AS failure.54028.test
FINAL VERSION OF TEST, WITH LOGGED REPLAY:
component3 = "epsilon"                                                   # STEP 0
ACTION: component3 = "epsilon" 
component3 = None : <type 'NoneType'>
=> component3 = 'epsilon' : <type 'str'>
==================================================
component4 = "phi"                                                       # STEP 1
ACTION: component4 = "phi" 
component4 = None : <type 'NoneType'>
=> component4 = 'phi' : <type 'str'>
==================================================
bytes4 = 0                                                               # STEP 2
ACTION: bytes4 = 0 
bytes4 = None : <type 'NoneType'>
=> bytes4 = 0 : <type 'int'>
==================================================
component1 = "omega"                                                     # STEP 3
ACTION: component1 = "omega" 
component1 = None : <type 'NoneType'>
=> component1 = 'omega' : <type 'str'>
==================================================
os0 = newFakeOS()                                                        # STEP 4
ACTION: os0 = newFakeOS() 
os0 = None : <type 'NoneType'>
os_REF0 = None : <type 'NoneType'>
RAISED EXCEPTION: <type 'exceptions.TypeError'> an integer is required
ERROR: (<type 'exceptions.TypeError'>, TypeError('an integer is required',), <traceback object at 0x105cc0d40>)
TRACEBACK:
  File "/Users/alex/tstl/examples/mutateProbe/pyfakefs/sut.py", line 48329, in safely
    act[2]()
  File "/Users/alex/tstl/examples/mutateProbe/pyfakefs/sut.py", line 66, in act0
    self.p_os[0] = newFakeOS()
  File "/Users/alex/tstl/examples/mutateProbe/pyfakefs/sut.py", line 21, in newFakeOS
    fs.CreateDirectory('/Volumes')
  File "/Users/alex/tstl/examples/mutateProbe/pyfakefs/pyfakefs/fake_filesystem.py", line 2055, in CreateDirectory
    if self.Exists(directory_path):
  File "/Users/alex/tstl/examples/mutateProbe/pyfakefs/pyfakefs/fake_filesystem.py", line 1624, in Exists
    file_path = self.ResolvePath(file_path)
  File "/Users/alex/tstl/examples/mutateProbe/pyfakefs/pyfakefs/fake_filesystem.py", line 1704, in ResolvePath
    return self.GetOpenFile(file_path).GetObject().GetPath()
  File "/Users/alex/tstl/examples/mutateProbe/pyfakefs/pyfakefs/fake_filesystem.py", line 1209, in GetOpenFile
    raise TypeError('an integer is required')
STOPPING TESTING DUE TO FAILED TEST
0.022118806839 TOTAL RUNTIME
1 EXECUTED
5 TOTAL TEST OPERATIONS
0.000381708145142 TIME SPENT EXECUTING TEST OPERATIONS
0.000231981277466 TIME SPENT EVALUATING GUARDS AND CHOOSING ACTIONS
2.86102294922e-06 TIME SPENT CHECKING PROPERTIES
0.000384569168091 TOTAL TIME SPENT RUNNING SUT
0.00428509712219 TIME SPENT RESTARTING
0.0 TIME SPENT REDUCING TEST CASES
