Random testing using config=Config(swarmSwitch=None, maxMustHitBranch=None, verbose=False, reducePool=False, failedLogging=None, exploitBestHint=1, greedyStutter=False, internal=False, exploit=None, seed=None, generalize=False, fastQuickAnalysis=False, stopWhenNoCoverage=None, useHints=False, localize=False, total=False, speed='FAST', probs=None, normalize=False, verboseExploit=False, highLowSwarm=None, replayable=False, essentials=False, maxMustHitStatement=None, noCoverageExploit=False, quickTests=False, relax=False, startExploitStall=0, enumerateEnabled=False, uniqueValuesAnalysis=False, swarm=False, noReassign=False, html=None, stopWhenHitStatement=None, biasLOC=None, progress=False, postCover=False, swarmLength=None, generateLOC=None, noSwarmDependencies=False, profile=False, LOCBaseline=0.2, noEnumerateEnabled=False, full=True, multiple=False, timedProgress=30, silentFail=False, ddmin=False, swarmP=0.5, stopWhenBranches=None, noAlphaConvert=False, coverFile='coverage.out', readQuick=False, verboseActions=False, running=False, computeFeatureStats=False, compareFails=False, swarmProbs=None, output='failure.59992.test', genDepth=None, Pcrossover=0.2, quickAnalysis=False, keepLast=False, exploitCeiling=0.1, markovP=1.0, logging=None, stopWhenHitBranch=None, LOCProbs=False, stopWhenStatements=None, noCheck=False, maxTests=-1, noExceptionMatch=False, Pmutate=0.0, depth=200, trackMaxCoverage=None, throughput=False, noCover=True, timeout=60, stutter=None, uncaught=False, markov=None, showActions=False, startExploit=0.0)
UNCAUGHT EXCEPTION
ERROR: (<type 'exceptions.OSError'>, OSError(17, 'Directory exists in fake filesystem'), <traceback object at 0x1024ae8c0>)
TRACEBACK:
  File "/Users/alex/tstl/examples/mutateProbe/pyfakefs/sut.py", line 48329, in safely
    act[2]()
  File "/Users/alex/tstl/examples/mutateProbe/pyfakefs/sut.py", line 66, in act0
    self.p_os[0] = newFakeOS()
  File "/Users/alex/tstl/examples/mutateProbe/pyfakefs/sut.py", line 22, in newFakeOS
    fs.CreateDirectory('/Volumes/ramdisk')
  File "/Users/alex/tstl/examples/mutateProbe/pyfakefs/pyfakefs/fake_filesystem.py", line 2059, in CreateDirectory
    raise OSError(errno.EEXIST, 'Directory exists in fake filesystem', directory_path)
Original test has 5 steps

SAVING TEST AS failure.59992.test
FINAL VERSION OF TEST, WITH LOGGED REPLAY:
component3 = "d"                                                         # STEP 0
ACTION: component3 = "d" 
component3 = None : <type 'NoneType'>
=> component3 = 'd' : <type 'str'>
==================================================
component0 = "phi"                                                       # STEP 1
ACTION: component0 = "phi" 
component0 = None : <type 'NoneType'>
=> component0 = 'phi' : <type 'str'>
==================================================
component1 = "delta"                                                     # STEP 2
ACTION: component1 = "delta" 
component1 = None : <type 'NoneType'>
=> component1 = 'delta' : <type 'str'>
==================================================
component2 = "e"                                                         # STEP 3
ACTION: component2 = "e" 
component2 = None : <type 'NoneType'>
=> component2 = 'e' : <type 'str'>
==================================================
os0 = newFakeOS()                                                        # STEP 4
ACTION: os0 = newFakeOS() 
os0 = None : <type 'NoneType'>
os_REF0 = None : <type 'NoneType'>
RAISED EXCEPTION: <type 'exceptions.OSError'> [Errno 17] Directory exists in fake filesystem: '/Volumes/ramdisk'
ERROR: (<type 'exceptions.OSError'>, OSError(17, 'Directory exists in fake filesystem'), <traceback object at 0x1025a4bd8>)
TRACEBACK:
  File "/Users/alex/tstl/examples/mutateProbe/pyfakefs/sut.py", line 48329, in safely
    act[2]()
  File "/Users/alex/tstl/examples/mutateProbe/pyfakefs/sut.py", line 66, in act0
    self.p_os[0] = newFakeOS()
  File "/Users/alex/tstl/examples/mutateProbe/pyfakefs/sut.py", line 22, in newFakeOS
    fs.CreateDirectory('/Volumes/ramdisk')
  File "/Users/alex/tstl/examples/mutateProbe/pyfakefs/pyfakefs/fake_filesystem.py", line 2059, in CreateDirectory
    raise OSError(errno.EEXIST, 'Directory exists in fake filesystem', directory_path)
STOPPING TESTING DUE TO FAILED TEST
0.0184662342072 TOTAL RUNTIME
1 EXECUTED
5 TOTAL TEST OPERATIONS
0.000375986099243 TIME SPENT EXECUTING TEST OPERATIONS
0.000643730163574 TIME SPENT EVALUATING GUARDS AND CHOOSING ACTIONS
2.14576721191e-06 TIME SPENT CHECKING PROPERTIES
0.000378131866455 TOTAL TIME SPENT RUNNING SUT
0.0032000541687 TIME SPENT RESTARTING
0.0 TIME SPENT REDUCING TEST CASES
